Workbook

Sheet Danh mục
A1: \9 | B1: Ngày bắt đầu | C1: Ngày kết thúc | D1: Mốc chính của tuần | F1: Tên thành viên | G1: Vai trò | I1: Trạng thái | J1: Ưu tiên | K1: Cổng | L1: Rubric
A2: Tuần 01 | B2: 46286 | C2: 46292 | D2: Khởi tạo nền tảng, Docker, Repo, Phân tích thị trường | F2: Nguyễn Tấn Phát | G2: PO & BA | I2: Backlog | J2: Khẩn cấp | K2: G1 | L2: 46027
A3: Tuần 02 | B3: 46293 | C3: 46299 | D3: Lean Canvas, Kanban, Setup Custom Plugin & Theme UI Tokens | F3: Lê Nguyễn Quốc An | G3: Scrum Master & DevOps | I3: To Do | J3: Cao | K3: G2 | L3: 46058
A4: Tuần 03 | B4: 46300 | C4: 46306 | D4: Hạn chốt G3 (L01, L02, L08, L09), Crawl >= 500 SKU | F4: Lâm Trúc Uyên | G4: Theme Dev 1 (Catalog, UI) | I4: In Progress | J4: Trung bình | K4: G3 | L4: 46086
A5: Tuần 04 | B5: 46307 | C5: 46313 | D5: Hạn chốt G3 (L03, L04, L05), Code Đợt A (Quiz, Catalog, Hạ tầng) | F5: Huỳnh Ngọc Nhã Uyên | G5: Theme Dev 2 (Quiz Frontend, Cart/Checkout UX) | I5: Review | J5: Thấp | K5: G4 | L5: 46117
A6: Tuần 05 | B6: 46314 | C6: 46320 | D6: Hạn chốt G3 (L06, L07), Import >= 500 SKU đủ 3 taxonomy | F6: Bùi Hiếu Nhân | G6: Plugin Dev 1 (Quiz Backend, Taxonomy, REST) | I6: Testing | K6: G5 | L6: 46147
A7: Tuần 06 | B7: 46321 | C7: 46327 | D7: Hạn chốt G3 (L10), Bật HPOS WooCommerce | F7: Nguyễn Minh Trí | G7: Plugin Dev 2 (Crawler, HPOS, Redis, khuyến mãi) | I7: Done | K7: G6 | L7: 46178
A8: Tuần 07 | B8: 46328 | C8: 46334 | D8: Redis Object Cache Connected, Chốt REST namespace | F8: Trần Ngọc Minh Tuyền | G8: Integration Dev (thanh toán, email, vận chuyển, REST API) | I8: Blocked | K8: G7 | L8: Không
A9: Tuần 08 | B9: 46335 | C9: 46341 | D9: Website VPS domain HTTPS (Rubric 5.1), Selenium 3 tác vụ (5.5), REST API 3 tác vụ (5.6) | F9: Nguyễn Ngọc Thảo Uyên | G9: QA & Automation (Selenium) | K9: G8
A10: Tuần 09 | B10: 46342 | C10: 46348 | D10: Load test 50 users, Regression test Selenium 5/5 lần, Script Python gọi REST
A11: Tuần 10 | B11: 46349 | C11: 46355 | D11: Tổng duyệt, hoàn thiện báo cáo Word, slide, video 4K, Demo Day

Sheet Luồng
A1: Mã luồng | B1: Tên | C1: Nhóm | D1: Mục tiêu | E1: Bắt đầu khi | F1: Kết thúc khi | G1: Nhận từ luồng | H1: Bàn giao cho luồng | I1: Flow Owner | J1: PO duyệt | K1: SM duyệt | L1: QA | M1: Ưu tiên | N1: Hạn chốt G3 | O1: Rubric liên quan | P1: G1 | Q1: G2 | R1: G3 | S1: G4 | T1: G5 | U1: G6 | V1: G7 | W1: G8 | X1: % hoàn thành | Y1: Sẵn sàng prompt? | Z1: Link thư mục docs/flows/...
A2: L01 | B2: Quiz chẩn đoán da & Routine cá nhân hóa | C2: Chuỗi khách hàng | D2: Giúp khách hàng nhận diện đúng loại da và nhận Routine 3-4 sản phẩm phù hợp qua bài trắc nghiệm. | E2: Khách bấm "Làm Quiz" | F2: Hiển thị Routine 3–4 sản phẩm | G2: L08 | H2: L02, L03 | I2: Bùi Hiếu Nhân | J2: Nguyễn Tấn Phát | K2: Lê Nguyễn Quốc An | L2: Nguyễn Ngọc Thảo Uyên | M2: Must | N2: 46306 | O2: Không | P2: =COUNTIFS(Tasks!$B$2:$B$137,A2,Tasks!$C$2:$C$137,"G1",Tasks!$Q$2:$Q$137,"Done")&"/"&COUNTIFS(Tasks!$B$2:$B$137,A2,Tasks!$C$2:$C$137,"G1") -> 0/0 | Q2: =COUNTIFS(Tasks!$B$2:$B$137,A2,Tasks!$C$2:$C$137,"G2",Tasks!$Q$2:$Q$137,"Done")&"/"&COUNTIFS(Tasks!$B$2:$B$137,A2,Tasks!$C$2:$C$137,"G2") -> 0/0 | R2: =COUNTIFS(Tasks!$B$2:$B$137,A2,Tasks!$C$2:$C$137,"G3",Tasks!$Q$2:$Q$137,"Done")&"/"&COUNTIFS(Tasks!$B$2:$B$137,A2,Tasks!$C$2:$C$137,"G3") -> 0/0 | S2: =COUNTIFS(Tasks!$B$2:$B$137,A2,Tasks!$C$2:$C$137,"G4",Tasks!$Q$2:$Q$137,"Done")&"/"&COUNTIFS(Tasks!$B$2:$B$137,A2,Tasks!$C$2:$C$137,"G4") -> 0/0 | T2: =COUNTIFS(Tasks!$B$2:$B$137,A2,Tasks!$C$2:$C$137,"G5",Tasks!$Q$2:$Q$137,"Done")&"/"&COUNTIFS(Tasks!$B$2:$B$137,A2,Tasks!$C$2:$C$137,"G5") -> 0/0 | U2: =COUNTIFS(Tasks!$B$2:$B$137,A2,Tasks!$C$2:$C$137,"G6",Tasks!$Q$2:$Q$137,"Done")&"/"&COUNTIFS(Tasks!$B$2:$B$137,A2,Tasks!$C$2:$C$137,"G6") -> 0/0 | V2: =COUNTIFS(Tasks!$B$2:$B$137,A2,Tasks!$C$2:$C$137,"G7",Tasks!$Q$2:$Q$137,"Done")&"/"&COUNTIFS(Tasks!$B$2:$B$137,A2,Tasks!$C$2:$C$137,"G7") -> 0/0 | W2: =COUNTIFS(Tasks!$B$2:$B$137,A2,Tasks!$C$2:$C$137,"G8",Tasks!$Q$2:$Q$137,"Done")&"/"&COUNTIFS(Tasks!$B$2:$B$137,A2,Tasks!$C$2:$C$137,"G8") -> 0/0 | X2: =IFERROR(COUNTIFS(Tasks!$B$2:$B$137,A2,Tasks!$Q$2:$Q$137,"Done")/COUNTIF(Tasks!$B$2:$B$137,A2),0) -> 0 | Y2: =IFERROR(VLOOKUP(A2,DoR!$A$2:$K$12,11,FALSE),"CHƯA SẴN SÀNG") -> CHƯA SẴN SÀNG | Z2: docs/flows/L01-quiz-routine/
A3: L02 | B3: Khám phá & chọn sản phẩm (Catalog, lọc, chi tiết) | C3: Chuỗi khách hàng | D3: Cung cấp giao diện duyệt sản phẩm, lọc theo đa tiêu chí taxonomy và xem chi tiết sản phẩm chuẩn UX. | E3: Khách vào web/tìm kiếm | F3: Bấm "Thêm vào giỏ" | G3: L08 | H3: L03 | I3: Lâm Trúc Uyên | J3: Nguyễn Tấn Phát | K3: Lê Nguyễn Quốc An | L3: Nguyễn Ngọc Thảo Uyên | M3: Must | N3: 46306 | O3: Không | P3: =COUNTIFS(Tasks!$B$2:$B$137,A3,Tasks!$C$2:$C$137,"G1",Tasks!$Q$2:$Q$137,"Done")&"/"&COUNTIFS(Tasks!$B$2:$B$137,A3,Tasks!$C$2:$C$137,"G1") -> 0/0 | Q3: =COUNTIFS(Tasks!$B$2:$B$137,A3,Tasks!$C$2:$C$137,"G2",Tasks!$Q$2:$Q$137,"Done")&"/"&COUNTIFS(Tasks!$B$2:$B$137,A3,Tasks!$C$2:$C$137,"G2") -> 0/0 | R3: =COUNTIFS(Tasks!$B$2:$B$137,A3,Tasks!$C$2:$C$137,"G3",Tasks!$Q$2:$Q$137,"Done")&"/"&COUNTIFS(Tasks!$B$2:$B$137,A3,Tasks!$C$2:$C$137,"G3") -> 0/0 | S3: =COUNTIFS(Tasks!$B$2:$B$137,A3,Tasks!$C$2:$C$137,"G4",Tasks!$Q$2:$Q$137,"Done")&"/"&COUNTIFS(Tasks!$B$2:$B$137,A3,Tasks!$C$2:$C$137,"G4") -> 0/0 | T3: =COUNTIFS(Tasks!$B$2:$B$137,A3,Tasks!$C$2:$C$137,"G5",Tasks!$Q$2:$Q$137,"Done")&"/"&COUNTIFS(Tasks!$B$2:$B$137,A3,Tasks!$C$2:$C$137,"G5") -> 0/0 | U3: =COUNTIFS(Tasks!$B$2:$B$137,A3,Tasks!$C$2:$C$137,"G6",Tasks!$Q$2:$Q$137,"Done")&"/"&COUNTIFS(Tasks!$B$2:$B$137,A3,Tasks!$C$2:$C$137,"G6") -> 0/0 | V3: =COUNTIFS(Tasks!$B$2:$B$137,A3,Tasks!$C$2:$C$137,"G7",Tasks!$Q$2:$Q$137,"Done")&"/"&COUNTIFS(Tasks!$B$2:$B$137,A3,Tasks!$C$2:$C$137,"G7") -> 0/0 | W3: =COUNTIFS(Tasks!$B$2:$B$137,A3,Tasks!$C$2:$C$137,"G8",Tasks!$Q$2:$Q$137,"Done")&"/"&COUNTIFS(Tasks!$B$2:$B$137,A3,Tasks!$C$2:$C$137,"G8") -> 0/0 | X3: =IFERROR(COUNTIFS(Tasks!$B$2:$B$137,A3,Tasks!$Q$2:$Q$137,"Done")/COUNTIF(Tasks!$B$2:$B$137,A3),0) -> 0 | Y3: =IFERROR(VLOOKUP(A3,DoR!$A$2:$K$12,11,FALSE),"CHƯA SẴN SÀNG") -> CHƯA SẴN SÀNG | Z3: docs/flows/L02-catalog-product/
A4: L03 | B4: Giỏ hàng & Combo Routine | C4: Chuỗi khách hàng | D4: Quản lý giỏ hàng mượt mà, tự động áp dụng giảm giá 10% combo routine và cảnh báo xung đột hoạt chất. | E4: Thêm vào giỏ (kể cả 1-click Routine) | F4: Bấm "Thanh toán" | G4: L01, L02 | H4: L04 | I4: Huỳnh Ngọc Nhã Uyên | J4: Nguyễn Tấn Phát | K4: Lê Nguyễn Quốc An | L4: Nguyễn Ngọc Thảo Uyên | M4: Must | N4: 46313 | O4: Không | P4: =COUNTIFS(Tasks!$B$2:$B$137,A4,Tasks!$C$2:$C$137,"G1",Tasks!$Q$2:$Q$137,"Done")&"/"&COUNTIFS(Tasks!$B$2:$B$137,A4,Tasks!$C$2:$C$137,"G1") -> 0/0 | Q4: =COUNTIFS(Tasks!$B$2:$B$137,A4,Tasks!$C$2:$C$137,"G2",Tasks!$Q$2:$Q$137,"Done")&"/"&COUNTIFS(Tasks!$B$2:$B$137,A4,Tasks!$C$2:$C$137,"G2") -> 0/0 | R4: =COUNTIFS(Tasks!$B$2:$B$137,A4,Tasks!$C$2:$C$137,"G3",Tasks!$Q$2:$Q$137,"Done")&"/"&COUNTIFS(Tasks!$B$2:$B$137,A4,Tasks!$C$2:$C$137,"G3") -> 0/0 | S4: =COUNTIFS(Tasks!$B$2:$B$137,A4,Tasks!$C$2:$C$137,"G4",Tasks!$Q$2:$Q$137,"Done")&"/"&COUNTIFS(Tasks!$B$2:$B$137,A4,Tasks!$C$2:$C$137,"G4") -> 0/0 | T4: =COUNTIFS(Tasks!$B$2:$B$137,A4,Tasks!$C$2:$C$137,"G5",Tasks!$Q$2:$Q$137,"Done")&"/"&COUNTIFS(Tasks!$B$2:$B$137,A4,Tasks!$C$2:$C$137,"G5") -> 0/0 | U4: =COUNTIFS(Tasks!$B$2:$B$137,A4,Tasks!$C$2:$C$137,"G6",Tasks!$Q$2:$Q$137,"Done")&"/"&COUNTIFS(Tasks!$B$2:$B$137,A4,Tasks!$C$2:$C$137,"G6") -> 0/0 | V4: =COUNTIFS(Tasks!$B$2:$B$137,A4,Tasks!$C$2:$C$137,"G7",Tasks!$Q$2:$Q$137,"Done")&"/"&COUNTIFS(Tasks!$B$2:$B$137,A4,Tasks!$C$2:$C$137,"G7") -> 0/0 | W4: =COUNTIFS(Tasks!$B$2:$B$137,A4,Tasks!$C$2:$C$137,"G8",Tasks!$Q$2:$Q$137,"Done")&"/"&COUNTIFS(Tasks!$B$2:$B$137,A4,Tasks!$C$2:$C$137,"G8") -> 0/0 | X4: =IFERROR(COUNTIFS(Tasks!$B$2:$B$137,A4,Tasks!$Q$2:$Q$137,"Done")/COUNTIF(Tasks!$B$2:$B$137,A4),0) -> 0 | Y4: =IFERROR(VLOOKUP(A4,DoR!$A$2:$K$12,11,FALSE),"CHƯA SẴN SÀNG") -> CHƯA SẴN SÀNG | Z4: docs/flows/L03-cart-combo/
A5: L04 | B5: Checkout & Thanh toán (COD, VietQR, VNPay Sandbox) | C5: Chuỗi khách hàng | D5: Xử lý thông tin giao hàng và tích hợp đa dạng cổng thanh toán an toàn, chính xác (Rubric 5.2). | E5: Nhập thông tin giao hàng | F5: Thanh toán được xác nhận | G5: L03 | H5: L05 | I5: Trần Ngọc Minh Tuyền | J5: Nguyễn Tấn Phát | K5: Lê Nguyễn Quốc An | L5: Nguyễn Ngọc Thảo Uyên | M5: Must | N5: 46313 | O5: 46058 | P5: =COUNTIFS(Tasks!$B$2:$B$137,A5,Tasks!$C$2:$C$137,"G1",Tasks!$Q$2:$Q$137,"Done")&"/"&COUNTIFS(Tasks!$B$2:$B$137,A5,Tasks!$C$2:$C$137,"G1") -> 0/0 | Q5: =COUNTIFS(Tasks!$B$2:$B$137,A5,Tasks!$C$2:$C$137,"G2",Tasks!$Q$2:$Q$137,"Done")&"/"&COUNTIFS(Tasks!$B$2:$B$137,A5,Tasks!$C$2:$C$137,"G2") -> 0/0 | R5: =COUNTIFS(Tasks!$B$2:$B$137,A5,Tasks!$C$2:$C$137,"G3",Tasks!$Q$2:$Q$137,"Done")&"/"&COUNTIFS(Tasks!$B$2:$B$137,A5,Tasks!$C$2:$C$137,"G3") -> 0/0 | S5: =COUNTIFS(Tasks!$B$2:$B$137,A5,Tasks!$C$2:$C$137,"G4",Tasks!$Q$2:$Q$137,"Done")&"/"&COUNTIFS(Tasks!$B$2:$B$137,A5,Tasks!$C$2:$C$137,"G4") -> 0/0 | T5: =COUNTIFS(Tasks!$B$2:$B$137,A5,Tasks!$C$2:$C$137,"G5",Tasks!$Q$2:$Q$137,"Done")&"/"&COUNTIFS(Tasks!$B$2:$B$137,A5,Tasks!$C$2:$C$137,"G5") -> 0/0 | U5: =COUNTIFS(Tasks!$B$2:$B$137,A5,Tasks!$C$2:$C$137,"G6",Tasks!$Q$2:$Q$137,"Done")&"/"&COUNTIFS(Tasks!$B$2:$B$137,A5,Tasks!$C$2:$C$137,"G6") -> 0/0 | V5: =COUNTIFS(Tasks!$B$2:$B$137,A5,Tasks!$C$2:$C$137,"G7",Tasks!$Q$2:$Q$137,"Done")&"/"&COUNTIFS(Tasks!$B$2:$B$137,A5,Tasks!$C$2:$C$137,"G7") -> 0/0 | W5: =COUNTIFS(Tasks!$B$2:$B$137,A5,Tasks!$C$2:$C$137,"G8",Tasks!$Q$2:$Q$137,"Done")&"/"&COUNTIFS(Tasks!$B$2:$B$137,A5,Tasks!$C$2:$C$137,"G8") -> 0/0 | X5: =IFERROR(COUNTIFS(Tasks!$B$2:$B$137,A5,Tasks!$Q$2:$Q$137,"Done")/COUNTIF(Tasks!$B$2:$B$137,A5),0) -> 0 | Y5: =IFERROR(VLOOKUP(A5,DoR!$A$2:$K$12,11,FALSE),"CHƯA SẴN SÀNG") -> CHƯA SẴN SÀNG | Z5: docs/flows/L04-checkout-payment/
A6: L05 | B6: Xử lý đơn hàng & Thông báo (vòng đời đơn, HPOS, tồn kho, email hóa đơn) | C6: Nền tảng | D6: Quản lý toàn bộ vòng đời đơn hàng, trừ tồn kho, tối ưu lưu trữ với HPOS (Rubric 5.3) và gửi email hóa đơn. | E6: Đơn được tạo | F6: Đơn sẵn sàng giao | G6: L04 | H6: L07, L06, L10 | I6: Nguyễn Minh Trí | J6: Nguyễn Tấn Phát | K6: Lê Nguyễn Quốc An | L6: Nguyễn Ngọc Thảo Uyên | M6: Must | N6: 46313 | O6: 46086 | P6: =COUNTIFS(Tasks!$B$2:$B$137,A6,Tasks!$C$2:$C$137,"G1",Tasks!$Q$2:$Q$137,"Done")&"/"&COUNTIFS(Tasks!$B$2:$B$137,A6,Tasks!$C$2:$C$137,"G1") -> 0/0 | Q6: =COUNTIFS(Tasks!$B$2:$B$137,A6,Tasks!$C$2:$C$137,"G2",Tasks!$Q$2:$Q$137,"Done")&"/"&COUNTIFS(Tasks!$B$2:$B$137,A6,Tasks!$C$2:$C$137,"G2") -> 0/0 | R6: =COUNTIFS(Tasks!$B$2:$B$137,A6,Tasks!$C$2:$C$137,"G3",Tasks!$Q$2:$Q$137,"Done")&"/"&COUNTIFS(Tasks!$B$2:$B$137,A6,Tasks!$C$2:$C$137,"G3") -> 0/0 | S6: =COUNTIFS(Tasks!$B$2:$B$137,A6,Tasks!$C$2:$C$137,"G4",Tasks!$Q$2:$Q$137,"Done")&"/"&COUNTIFS(Tasks!$B$2:$B$137,A6,Tasks!$C$2:$C$137,"G4") -> 0/0 | T6: =COUNTIFS(Tasks!$B$2:$B$137,A6,Tasks!$C$2:$C$137,"G5",Tasks!$Q$2:$Q$137,"Done")&"/"&COUNTIFS(Tasks!$B$2:$B$137,A6,Tasks!$C$2:$C$137,"G5") -> 0/0 | U6: =COUNTIFS(Tasks!$B$2:$B$137,A6,Tasks!$C$2:$C$137,"G6",Tasks!$Q$2:$Q$137,"Done")&"/"&COUNTIFS(Tasks!$B$2:$B$137,A6,Tasks!$C$2:$C$137,"G6") -> 0/0 | V6: =COUNTIFS(Tasks!$B$2:$B$137,A6,Tasks!$C$2:$C$137,"G7",Tasks!$Q$2:$Q$137,"Done")&"/"&COUNTIFS(Tasks!$B$2:$B$137,A6,Tasks!$C$2:$C$137,"G7") -> 0/0 | W6: =COUNTIFS(Tasks!$B$2:$B$137,A6,Tasks!$C$2:$C$137,"G8",Tasks!$Q$2:$Q$137,"Done")&"/"&COUNTIFS(Tasks!$B$2:$B$137,A6,Tasks!$C$2:$C$137,"G8") -> 0/0 | X6: =IFERROR(COUNTIFS(Tasks!$B$2:$B$137,A6,Tasks!$Q$2:$Q$137,"Done")/COUNTIF(Tasks!$B$2:$B$137,A6),0) -> 0 | Y6: =IFERROR(VLOOKUP(A6,DoR!$A$2:$K$12,11,FALSE),"CHƯA SẴN SÀNG") -> CHƯA SẴN SÀNG | Z6: docs/flows/L05-order-processing/
A7: L06 | B7: Vận chuyển & Giao hàng tận tay (phí ship, trạng thái giao, giao thất bại) | C7: Chuỗi khách hàng | D7: Mô phỏng quy trình tính phí vận chuyển và cập nhật trạng thái giao hàng tận tay khách hàng. | E7: Đơn sẵn sàng giao | F7: Khách nhận hàng hoặc giao thất bại | G7: L05 | H7: L07 (Đã giao là mốc tính 7 ngày) | I7: Trần Ngọc Minh Tuyền | J7: Nguyễn Tấn Phát | K7: Lê Nguyễn Quốc An | L7: Nguyễn Ngọc Thảo Uyên | M7: Should | N7: 46320 | O7: Không | P7: =COUNTIFS(Tasks!$B$2:$B$137,A7,Tasks!$C$2:$C$137,"G1",Tasks!$Q$2:$Q$137,"Done")&"/"&COUNTIFS(Tasks!$B$2:$B$137,A7,Tasks!$C$2:$C$137,"G1") -> 0/0 | Q7: =COUNTIFS(Tasks!$B$2:$B$137,A7,Tasks!$C$2:$C$137,"G2",Tasks!$Q$2:$Q$137,"Done")&"/"&COUNTIFS(Tasks!$B$2:$B$137,A7,Tasks!$C$2:$C$137,"G2") -> 0/0 | R7: =COUNTIFS(Tasks!$B$2:$B$137,A7,Tasks!$C$2:$C$137,"G3",Tasks!$Q$2:$Q$137,"Done")&"/"&COUNTIFS(Tasks!$B$2:$B$137,A7,Tasks!$C$2:$C$137,"G3") -> 0/0 | S7: =COUNTIFS(Tasks!$B$2:$B$137,A7,Tasks!$C$2:$C$137,"G4",Tasks!$Q$2:$Q$137,"Done")&"/"&COUNTIFS(Tasks!$B$2:$B$137,A7,Tasks!$C$2:$C$137,"G4") -> 0/0 | T7: =COUNTIFS(Tasks!$B$2:$B$137,A7,Tasks!$C$2:$C$137,"G5",Tasks!$Q$2:$Q$137,"Done")&"/"&COUNTIFS(Tasks!$B$2:$B$137,A7,Tasks!$C$2:$C$137,"G5") -> 0/0 | U7: =COUNTIFS(Tasks!$B$2:$B$137,A7,Tasks!$C$2:$C$137,"G6",Tasks!$Q$2:$Q$137,"Done")&"/"&COUNTIFS(Tasks!$B$2:$B$137,A7,Tasks!$C$2:$C$137,"G6") -> 0/0 | V7: =COUNTIFS(Tasks!$B$2:$B$137,A7,Tasks!$C$2:$C$137,"G7",Tasks!$Q$2:$Q$137,"Done")&"/"&COUNTIFS(Tasks!$B$2:$B$137,A7,Tasks!$C$2:$C$137,"G7") -> 0/0 | W7: =COUNTIFS(Tasks!$B$2:$B$137,A7,Tasks!$C$2:$C$137,"G8",Tasks!$Q$2:$Q$137,"Done")&"/"&COUNTIFS(Tasks!$B$2:$B$137,A7,Tasks!$C$2:$C$137,"G8") -> 0/0 | X7: =IFERROR(COUNTIFS(Tasks!$B$2:$B$137,A7,Tasks!$Q$2:$Q$137,"Done")/COUNTIF(Tasks!$B$2:$B$137,A7),0) -> 0 | Y7: =IFERROR(VLOOKUP(A7,DoR!$A$2:$K$12,11,FALSE),"CHƯA SẴN SÀNG") -> CHƯA SẴN SÀNG | Z7: docs/flows/L06-shipping-delivery/
A8: L07 | B8: Đổi trả & Hoàn tiền (7 ngày, kiểm hàng, hoàn tiền, nhập lại kho) | C8: Chuỗi khách hàng | D8: Tiếp nhận yêu cầu đổi trả trong 7 ngày, kiểm định sản phẩm, thực hiện hoàn tiền và nhập lại kho. | E8: Khách yêu cầu trả hàng | F8: Hoàn tiền xong và tồn kho cập nhật | G8: L06 | H8: L05 (nhập kho & hoàn tiền) | I8: Nguyễn Tấn Phát | J8: Nguyễn Tấn Phát | K8: Lê Nguyễn Quốc An | L8: Nguyễn Ngọc Thảo Uyên | M8: Should | N8: 46320 | O8: Không | P8: =COUNTIFS(Tasks!$B$2:$B$137,A8,Tasks!$C$2:$C$137,"G1",Tasks!$Q$2:$Q$137,"Done")&"/"&COUNTIFS(Tasks!$B$2:$B$137,A8,Tasks!$C$2:$C$137,"G1") -> 0/0 | Q8: =COUNTIFS(Tasks!$B$2:$B$137,A8,Tasks!$C$2:$C$137,"G2",Tasks!$Q$2:$Q$137,"Done")&"/"&COUNTIFS(Tasks!$B$2:$B$137,A8,Tasks!$C$2:$C$137,"G2") -> 0/0 | R8: =COUNTIFS(Tasks!$B$2:$B$137,A8,Tasks!$C$2:$C$137,"G3",Tasks!$Q$2:$Q$137,"Done")&"/"&COUNTIFS(Tasks!$B$2:$B$137,A8,Tasks!$C$2:$C$137,"G3") -> 0/0 | S8: =COUNTIFS(Tasks!$B$2:$B$137,A8,Tasks!$C$2:$C$137,"G4",Tasks!$Q$2:$Q$137,"Done")&"/"&COUNTIFS(Tasks!$B$2:$B$137,A8,Tasks!$C$2:$C$137,"G4") -> 0/0 | T8: =COUNTIFS(Tasks!$B$2:$B$137,A8,Tasks!$C$2:$C$137,"G5",Tasks!$Q$2:$Q$137,"Done")&"/"&COUNTIFS(Tasks!$B$2:$B$137,A8,Tasks!$C$2:$C$137,"G5") -> 0/0 | U8: =COUNTIFS(Tasks!$B$2:$B$137,A8,Tasks!$C$2:$C$137,"G6",Tasks!$Q$2:$Q$137,"Done")&"/"&COUNTIFS(Tasks!$B$2:$B$137,A8,Tasks!$C$2:$C$137,"G6") -> 0/0 | V8: =COUNTIFS(Tasks!$B$2:$B$137,A8,Tasks!$C$2:$C$137,"G7",Tasks!$Q$2:$Q$137,"Done")&"/"&COUNTIFS(Tasks!$B$2:$B$137,A8,Tasks!$C$2:$C$137,"G7") -> 0/0 | W8: =COUNTIFS(Tasks!$B$2:$B$137,A8,Tasks!$C$2:$C$137,"G8",Tasks!$Q$2:$Q$137,"Done")&"/"&COUNTIFS(Tasks!$B$2:$B$137,A8,Tasks!$C$2:$C$137,"G8") -> 0/0 | X8: =IFERROR(COUNTIFS(Tasks!$B$2:$B$137,A8,Tasks!$Q$2:$Q$137,"Done")/COUNTIF(Tasks!$B$2:$B$137,A8),0) -> 0 | Y8: =IFERROR(VLOOKUP(A8,DoR!$A$2:$K$12,11,FALSE),"CHƯA SẴN SÀNG") -> CHƯA SẴN SÀNG | Z8: docs/flows/L07-return-refund/
A9: L08 | B9: Dữ liệu sản phẩm >= 500 SKU (crawl -> làm sạch -> gán taxonomy -> import) | C9: Nền tảng | D9: Thu thập độc lập >= 500 SKU mỹ phẩm thật, chuẩn hóa taxonomy và import vào hệ thống (Rubric 5.4). | E9: Chọn nguồn | F9: >= 500 SKU đã import, đủ 3 taxonomy | G9: Không | H9: L01, L02 | I9: Nguyễn Minh Trí | J9: Nguyễn Tấn Phát | K9: Lê Nguyễn Quốc An | L9: Nguyễn Ngọc Thảo Uyên | M9: Must | N9: 46306 | O9: 46117 | P9: =COUNTIFS(Tasks!$B$2:$B$137,A9,Tasks!$C$2:$C$137,"G1",Tasks!$Q$2:$Q$137,"Done")&"/"&COUNTIFS(Tasks!$B$2:$B$137,A9,Tasks!$C$2:$C$137,"G1") -> 0/0 | Q9: =COUNTIFS(Tasks!$B$2:$B$137,A9,Tasks!$C$2:$C$137,"G2",Tasks!$Q$2:$Q$137,"Done")&"/"&COUNTIFS(Tasks!$B$2:$B$137,A9,Tasks!$C$2:$C$137,"G2") -> 0/0 | R9: =COUNTIFS(Tasks!$B$2:$B$137,A9,Tasks!$C$2:$C$137,"G3",Tasks!$Q$2:$Q$137,"Done")&"/"&COUNTIFS(Tasks!$B$2:$B$137,A9,Tasks!$C$2:$C$137,"G3") -> 0/0 | S9: =COUNTIFS(Tasks!$B$2:$B$137,A9,Tasks!$C$2:$C$137,"G4",Tasks!$Q$2:$Q$137,"Done")&"/"&COUNTIFS(Tasks!$B$2:$B$137,A9,Tasks!$C$2:$C$137,"G4") -> 0/0 | T9: =COUNTIFS(Tasks!$B$2:$B$137,A9,Tasks!$C$2:$C$137,"G5",Tasks!$Q$2:$Q$137,"Done")&"/"&COUNTIFS(Tasks!$B$2:$B$137,A9,Tasks!$C$2:$C$137,"G5") -> 0/0 | U9: =COUNTIFS(Tasks!$B$2:$B$137,A9,Tasks!$C$2:$C$137,"G6",Tasks!$Q$2:$Q$137,"Done")&"/"&COUNTIFS(Tasks!$B$2:$B$137,A9,Tasks!$C$2:$C$137,"G6") -> 0/0 | V9: =COUNTIFS(Tasks!$B$2:$B$137,A9,Tasks!$C$2:$C$137,"G7",Tasks!$Q$2:$Q$137,"Done")&"/"&COUNTIFS(Tasks!$B$2:$B$137,A9,Tasks!$C$2:$C$137,"G7") -> 0/0 | W9: =COUNTIFS(Tasks!$B$2:$B$137,A9,Tasks!$C$2:$C$137,"G8",Tasks!$Q$2:$Q$137,"Done")&"/"&COUNTIFS(Tasks!$B$2:$B$137,A9,Tasks!$C$2:$C$137,"G8") -> 0/0 | X9: =IFERROR(COUNTIFS(Tasks!$B$2:$B$137,A9,Tasks!$Q$2:$Q$137,"Done")/COUNTIF(Tasks!$B$2:$B$137,A9),0) -> 0 | Y9: =IFERROR(VLOOKUP(A9,DoR!$A$2:$K$12,11,FALSE),"CHƯA SẴN SÀNG") -> CHƯA SẴN SÀNG | Z9: docs/flows/L08-product-data/
A10: L09 | B10: Hạ tầng, Triển khai & Hiệu năng | C10: Nền tảng | D10: Đóng gói Docker đồng nhất, deploy Cloud VPS domain HTTPS (Rubric 5.1) và tăng tốc với Redis (Rubric 5.3). | E10: Repo/Docker local | F10: VPS domain HTTPS chạy ổn định, Redis/HPOS, load test | G10: Không | H10: Toàn hệ thống | I10: Lê Nguyễn Quốc An | J10: Nguyễn Tấn Phát | K10: Lê Nguyễn Quốc An | L10: Nguyễn Ngọc Thảo Uyên | M10: Must | N10: 46306 | O10: 5.1, 5.3 | P10: =COUNTIFS(Tasks!$B$2:$B$137,A10,Tasks!$C$2:$C$137,"G1",Tasks!$Q$2:$Q$137,"Done")&"/"&COUNTIFS(Tasks!$B$2:$B$137,A10,Tasks!$C$2:$C$137,"G1") -> 0/0 | Q10: =COUNTIFS(Tasks!$B$2:$B$137,A10,Tasks!$C$2:$C$137,"G2",Tasks!$Q$2:$Q$137,"Done")&"/"&COUNTIFS(Tasks!$B$2:$B$137,A10,Tasks!$C$2:$C$137,"G2") -> 0/0 | R10: =COUNTIFS(Tasks!$B$2:$B$137,A10,Tasks!$C$2:$C$137,"G3",Tasks!$Q$2:$Q$137,"Done")&"/"&COUNTIFS(Tasks!$B$2:$B$137,A10,Tasks!$C$2:$C$137,"G3") -> 0/0 | S10: =COUNTIFS(Tasks!$B$2:$B$137,A10,Tasks!$C$2:$C$137,"G4",Tasks!$Q$2:$Q$137,"Done")&"/"&COUNTIFS(Tasks!$B$2:$B$137,A10,Tasks!$C$2:$C$137,"G4") -> 0/0 | T10: =COUNTIFS(Tasks!$B$2:$B$137,A10,Tasks!$C$2:$C$137,"G5",Tasks!$Q$2:$Q$137,"Done")&"/"&COUNTIFS(Tasks!$B$2:$B$137,A10,Tasks!$C$2:$C$137,"G5") -> 0/0 | U10: =COUNTIFS(Tasks!$B$2:$B$137,A10,Tasks!$C$2:$C$137,"G6",Tasks!$Q$2:$Q$137,"Done")&"/"&COUNTIFS(Tasks!$B$2:$B$137,A10,Tasks!$C$2:$C$137,"G6") -> 0/0 | V10: =COUNTIFS(Tasks!$B$2:$B$137,A10,Tasks!$C$2:$C$137,"G7",Tasks!$Q$2:$Q$137,"Done")&"/"&COUNTIFS(Tasks!$B$2:$B$137,A10,Tasks!$C$2:$C$137,"G7") -> 0/0 | W10: =COUNTIFS(Tasks!$B$2:$B$137,A10,Tasks!$C$2:$C$137,"G8",Tasks!$Q$2:$Q$137,"Done")&"/"&COUNTIFS(Tasks!$B$2:$B$137,A10,Tasks!$C$2:$C$137,"G8") -> 0/0 | X10: =IFERROR(COUNTIFS(Tasks!$B$2:$B$137,A10,Tasks!$Q$2:$Q$137,"Done")/COUNTIF(Tasks!$B$2:$B$137,A10),0) -> 0 | Y10: =IFERROR(VLOOKUP(A10,DoR!$A$2:$K$12,11,FALSE),"CHƯA SẴN SÀNG") -> CHƯA SẴN SÀNG | Z10: docs/flows/L09-infra-devops/
A11: L10 | B11: Tự động hóa & API (Selenium + REST cùng 3 tác vụ) | C11: Nền tảng | D11: Tự động hóa kiểm thử Selenium (Rubric 5.5) và cung cấp REST API độc lập (Rubric 5.6) cho 3 tác vụ quản trị. | E11: Có đơn và sản phẩm mẫu | F11: 2 script chạy thành công | G11: L05, L08 | H11: Báo cáo môn học | I11: Nguyễn Ngọc Thảo Uyên | J11: Nguyễn Tấn Phát | K11: Lê Nguyễn Quốc An | L11: Bùi Hiếu Nhân | M11: Must | N11: 46327 | O11: 5.5, 5.6 | P11: =COUNTIFS(Tasks!$B$2:$B$137,A11,Tasks!$C$2:$C$137,"G1",Tasks!$Q$2:$Q$137,"Done")&"/"&COUNTIFS(Tasks!$B$2:$B$137,A11,Tasks!$C$2:$C$137,"G1") -> 0/0 | Q11: =COUNTIFS(Tasks!$B$2:$B$137,A11,Tasks!$C$2:$C$137,"G2",Tasks!$Q$2:$Q$137,"Done")&"/"&COUNTIFS(Tasks!$B$2:$B$137,A11,Tasks!$C$2:$C$137,"G2") -> 0/0 | R11: =COUNTIFS(Tasks!$B$2:$B$137,A11,Tasks!$C$2:$C$137,"G3",Tasks!$Q$2:$Q$137,"Done")&"/"&COUNTIFS(Tasks!$B$2:$B$137,A11,Tasks!$C$2:$C$137,"G3") -> 0/0 | S11: =COUNTIFS(Tasks!$B$2:$B$137,A11,Tasks!$C$2:$C$137,"G4",Tasks!$Q$2:$Q$137,"Done")&"/"&COUNTIFS(Tasks!$B$2:$B$137,A11,Tasks!$C$2:$C$137,"G4") -> 0/0 | T11: =COUNTIFS(Tasks!$B$2:$B$137,A11,Tasks!$C$2:$C$137,"G5",Tasks!$Q$2:$Q$137,"Done")&"/"&COUNTIFS(Tasks!$B$2:$B$137,A11,Tasks!$C$2:$C$137,"G5") -> 0/0 | U11: =COUNTIFS(Tasks!$B$2:$B$137,A11,Tasks!$C$2:$C$137,"G6",Tasks!$Q$2:$Q$137,"Done")&"/"&COUNTIFS(Tasks!$B$2:$B$137,A11,Tasks!$C$2:$C$137,"G6") -> 0/0 | V11: =COUNTIFS(Tasks!$B$2:$B$137,A11,Tasks!$C$2:$C$137,"G7",Tasks!$Q$2:$Q$137,"Done")&"/"&COUNTIFS(Tasks!$B$2:$B$137,A11,Tasks!$C$2:$C$137,"G7") -> 0/0 | W11: =COUNTIFS(Tasks!$B$2:$B$137,A11,Tasks!$C$2:$C$137,"G8",Tasks!$Q$2:$Q$137,"Done")&"/"&COUNTIFS(Tasks!$B$2:$B$137,A11,Tasks!$C$2:$C$137,"G8") -> 0/0 | X11: =IFERROR(COUNTIFS(Tasks!$B$2:$B$137,A11,Tasks!$Q$2:$Q$137,"Done")/COUNTIF(Tasks!$B$2:$B$137,A11),0) -> 0 | Y11: =IFERROR(VLOOKUP(A11,DoR!$A$2:$K$12,11,FALSE),"CHƯA SẴN SÀNG") -> CHƯA SẴN SÀNG | Z11: docs/flows/L10-automation-api/
A12: L00 | B12: Quản trị dự án, Báo cáo & Demo (Kanban, Daily, chương báo cáo, slide, video 4K, tổng duyệt) | C12: Nền tảng | D12: Quản trị tiến độ Agile/Scrum, kiểm soát tài liệu báo cáo Word, slide và tổ chức Demo Day hoàn hảo. | E12: Kickoff | F12: Demo Day | G12: Toàn hệ thống | H12: Giảng viên & Hội đồng | I12: Lê Nguyễn Quốc An | J12: Nguyễn Tấn Phát | K12: Lê Nguyễn Quốc An | L12: Nguyễn Ngọc Thảo Uyên | M12: Must | N12: 46306 | O12: Không | P12: =COUNTIFS(Tasks!$B$2:$B$137,A12,Tasks!$C$2:$C$137,"G1",Tasks!$Q$2:$Q$137,"Done")&"/"&COUNTIFS(Tasks!$B$2:$B$137,A12,Tasks!$C$2:$C$137,"G1") -> 0/0 | Q12: =COUNTIFS(Tasks!$B$2:$B$137,A12,Tasks!$C$2:$C$137,"G2",Tasks!$Q$2:$Q$137,"Done")&"/"&COUNTIFS(Tasks!$B$2:$B$137,A12,Tasks!$C$2:$C$137,"G2") -> 0/0 | R12: =COUNTIFS(Tasks!$B$2:$B$137,A12,Tasks!$C$2:$C$137,"G3",Tasks!$Q$2:$Q$137,"Done")&"/"&COUNTIFS(Tasks!$B$2:$B$137,A12,Tasks!$C$2:$C$137,"G3") -> 0/0 | S12: =COUNTIFS(Tasks!$B$2:$B$137,A12,Tasks!$C$2:$C$137,"G4",Tasks!$Q$2:$Q$137,"Done")&"/"&COUNTIFS(Tasks!$B$2:$B$137,A12,Tasks!$C$2:$C$137,"G4") -> 0/0 | T12: =COUNTIFS(Tasks!$B$2:$B$137,A12,Tasks!$C$2:$C$137,"G5",Tasks!$Q$2:$Q$137,"Done")&"/"&COUNTIFS(Tasks!$B$2:$B$137,A12,Tasks!$C$2:$C$137,"G5") -> 0/0 | U12: =COUNTIFS(Tasks!$B$2:$B$137,A12,Tasks!$C$2:$C$137,"G6",Tasks!$Q$2:$Q$137,"Done")&"/"&COUNTIFS(Tasks!$B$2:$B$137,A12,Tasks!$C$2:$C$137,"G6") -> 0/0 | V12: =COUNTIFS(Tasks!$B$2:$B$137,A12,Tasks!$C$2:$C$137,"G7",Tasks!$Q$2:$Q$137,"Done")&"/"&COUNTIFS(Tasks!$B$2:$B$137,A12,Tasks!$C$2:$C$137,"G7") -> 0/0 | W12: =COUNTIFS(Tasks!$B$2:$B$137,A12,Tasks!$C$2:$C$137,"G8",Tasks!$Q$2:$Q$137,"Done")&"/"&COUNTIFS(Tasks!$B$2:$B$137,A12,Tasks!$C$2:$C$137,"G8") -> 0/0 | X12: =IFERROR(COUNTIFS(Tasks!$B$2:$B$137,A12,Tasks!$Q$2:$Q$137,"Done")/COUNTIF(Tasks!$B$2:$B$137,A12),0) -> 0 | Y12: =IFERROR(VLOOKUP(A12,DoR!$A$2:$K$12,11,FALSE),"CHƯA SẴN SÀNG") -> CHƯA SẴN SÀNG | Z12: docs/flows/L00-project-management/

Sheet RACI
A1: Mã luồng | B1: Tên luồng | C1: Nguyễn Tấn Phát | D1: Lê Nguyễn Quốc An | E1: Lâm Trúc Uyên | F1: Huỳnh Ngọc Nhã Uyên | G1: Bùi Hiếu Nhân | H1: Nguyễn Minh Trí | I1: Trần Ngọc Minh Tuyền | J1: Nguyễn Ngọc Thảo Uyên | K1: Kiểm tra
A2: L01 | B2: Quiz chẩn đoán da & Routine cá nhân hóa | C2: R | D2: C | E2: I | F2: R | G2: A | H2: I | I2: I | J2: C | K2: =IF(COUNTIF(C2:J2,"A")=1,"ĐẠT","LỖI") -> ĐẠT
A3: L02 | B3: Khám phá & chọn sản phẩm (Catalog, lọc, chi tiết) | C3: R | D3: I | E3: A | F3: C | G3: I | H3: R | I3: I | J3: C | K3: =IF(COUNTIF(C3:J3,"A")=1,"ĐẠT","LỖI") -> ĐẠT
A4: L03 | B4: Giỏ hàng & Combo Routine | C4: C | D4: I | E4: C | F4: A | G4: I | H4: R | I4: I | J4: C | K4: =IF(COUNTIF(C4:J4,"A")=1,"ĐẠT","LỖI") -> ĐẠT
A5: L04 | B5: Checkout & Thanh toán (COD, VietQR, VNPay Sandbox) | C5: C | D5: I | E5: I | F5: R | G5: I | H5: I | I5: A | J5: C | K5: =IF(COUNTIF(C5:J5,"A")=1,"ĐẠT","LỖI") -> ĐẠT
A6: L05 | B6: Xử lý đơn hàng & Thông báo (vòng đời đơn, HPOS, tồn kho, email hóa đơn) | C6: R | D6: C | E6: I | F6: I | G6: I | H6: A | I6: R | J6: C | K6: =IF(COUNTIF(C6:J6,"A")=1,"ĐẠT","LỖI") -> ĐẠT
A7: L06 | B7: Vận chuyển & Giao hàng tận tay (phí ship, trạng thái giao, giao thất bại) | C7: C | D7: I | E7: R | F7: I | G7: I | H7: R | I7: A | J7: C | K7: =IF(COUNTIF(C7:J7,"A")=1,"ĐẠT","LỖI") -> ĐẠT
A8: L07 | B8: Đổi trả & Hoàn tiền (7 ngày, kiểm hàng, hoàn tiền, nhập lại kho) | C8: A | D8: C | E8: R | F8: I | G8: R | H8: C | I8: R | J8: C | K8: =IF(COUNTIF(C8:J8,"A")=1,"ĐẠT","LỖI") -> ĐẠT
A9: L08 | B9: Dữ liệu sản phẩm >= 500 SKU (crawl -> làm sạch -> gán taxonomy -> import) | C9: R | D9: I | E9: I | F9: I | G9: C | H9: A | I9: I | J9: R | K9: =IF(COUNTIF(C9:J9,"A")=1,"ĐẠT","LỖI") -> ĐẠT
A10: L09 | B10: Hạ tầng, Triển khai & Hiệu năng | C10: C | D10: A | E10: I | F10: I | G10: C | H10: R | I10: C | J10: R | K10: =IF(COUNTIF(C10:J10,"A")=1,"ĐẠT","LỖI") -> ĐẠT
A11: L10 | B11: Tự động hóa & API (Selenium + REST cùng 3 tác vụ) | C11: C | D11: C | E11: I | F11: I | G11: R | H11: C | I11: R | J11: A | K11: =IF(COUNTIF(C11:J11,"A")=1,"ĐẠT","LỖI") -> ĐẠT
A12: L00 | B12: Quản trị dự án, Báo cáo & Demo | C12: R | D12: A | E12: C | F12: I | G12: I | H12: I | I12: I | J12: C | K12: =IF(COUNTIF(C12:J12,"A")=1,"ĐẠT","LỖI") -> ĐẠT

Sheet DoR
A1: Mã luồng | B1: Tên luồng | C1: (1) Flow Card đủ mục | D1: (2) Sơ đồ luồng chính đã vẽ và PO duyệt | E1: (3) Trạng thái/State đã định nghĩa | F1: (4) Dữ liệu, bảng, meta, taxonomy đã liệt kê | G1: (5) Endpoint/hook đã chốt | H1: (6) Tiêu chí chấp nhận >= 5 (Given-When-Then) | I1: (7) Ràng buộc kỹ thuật đã ghi | J1: (8) Dữ liệu/kịch bản test mẫu | K1: Trạng thái DoR
A2: L01 | B2: Luồng 01 | C2: FALSE | D2: FALSE | E2: FALSE | F2: FALSE | G2: FALSE | H2: FALSE | I2: FALSE | J2: FALSE | K2: =IF(COUNTIF(C2:J2,TRUE)=8,"SẴN SÀNG PROMPT","CHƯA SẴN SÀNG") -> CHƯA SẴN SÀNG
A3: L02 | B3: Luồng 02 | C3: FALSE | D3: FALSE | E3: FALSE | F3: FALSE | G3: FALSE | H3: FALSE | I3: FALSE | J3: FALSE | K3: =IF(COUNTIF(C3:J3,TRUE)=8,"SẴN SÀNG PROMPT","CHƯA SẴN SÀNG") -> CHƯA SẴN SÀNG
A4: L03 | B4: Luồng 03 | C4: FALSE | D4: FALSE | E4: FALSE | F4: FALSE | G4: FALSE | H4: FALSE | I4: FALSE | J4: FALSE | K4: =IF(COUNTIF(C4:J4,TRUE)=8,"SẴN SÀNG PROMPT","CHƯA SẴN SÀNG") -> CHƯA SẴN SÀNG
A5: L04 | B5: Luồng 04 | C5: FALSE | D5: FALSE | E5: FALSE | F5: FALSE | G5: FALSE | H5: FALSE | I5: FALSE | J5: FALSE | K5: =IF(COUNTIF(C5:J5,TRUE)=8,"SẴN SÀNG PROMPT","CHƯA SẴN SÀNG") -> CHƯA SẴN SÀNG
A6: L05 | B6: Luồng 05 | C6: FALSE | D6: FALSE | E6: FALSE | F6: FALSE | G6: FALSE | H6: FALSE | I6: FALSE | J6: FALSE | K6: =IF(COUNTIF(C6:J6,TRUE)=8,"SẴN SÀNG PROMPT","CHƯA SẴN SÀNG") -> CHƯA SẴN SÀNG
A7: L06 | B7: Luồng 06 | C7: FALSE | D7: FALSE | E7: FALSE | F7: FALSE | G7: FALSE | H7: FALSE | I7: FALSE | J7: FALSE | K7: =IF(COUNTIF(C7:J7,TRUE)=8,"SẴN SÀNG PROMPT","CHƯA SẴN SÀNG") -> CHƯA SẴN SÀNG
A8: L07 | B8: Luồng 07 | C8: FALSE | D8: FALSE | E8: FALSE | F8: FALSE | G8: FALSE | H8: FALSE | I8: FALSE | J8: FALSE | K8: =IF(COUNTIF(C8:J8,TRUE)=8,"SẴN SÀNG PROMPT","CHƯA SẴN SÀNG") -> CHƯA SẴN SÀNG
A9: L08 | B9: Luồng 08 | C9: TRUE | D9: TRUE | E9: TRUE | F9: TRUE | G9: TRUE | H9: TRUE | I9: TRUE | J9: TRUE | K9: =IF(COUNTIF(C9:J9,TRUE)=8,"SẴN SÀNG PROMPT","CHƯA SẴN SÀNG") -> SẴN SÀNG PROMPT
A10: L09 | B10: Luồng 09 | C10: TRUE | D10: TRUE | E10: TRUE | F10: TRUE | G10: TRUE | H10: TRUE | I10: TRUE | J10: TRUE | K10: =IF(COUNTIF(C10:J10,TRUE)=8,"SẴN SÀNG PROMPT","CHƯA SẴN SÀNG") -> SẴN SÀNG PROMPT
A11: L10 | B11: Luồng 10 | C11: FALSE | D11: FALSE | E11: FALSE | F11: FALSE | G11: FALSE | H11: FALSE | I11: FALSE | J11: FALSE | K11: =IF(COUNTIF(C11:J11,TRUE)=8,"SẴN SÀNG PROMPT","CHƯA SẴN SÀNG") -> CHƯA SẴN SÀNG
A12: L00 | B12: Luồng 00 | C12: FALSE | D12: FALSE | E12: FALSE | F12: FALSE | G12: FALSE | H12: FALSE | I12: FALSE | J12: FALSE | K12: =IF(COUNTIF(C12:J12,TRUE)=8,"SẴN SÀNG PROMPT","CHƯA SẴN SÀNG") -> CHƯA SẴN SÀNG

Sheet Prompt Log
A1: Mã prompt | B1: Mã task | C1: Luồng | D1: Người viết | E1: Agent/Model | F1: Phiên bản | G1: Tài liệu đính kèm | H1: Nội dung prompt | I1: Kết quả | J1: Lý do sửa | K1: Link PR | L1: Ngày
A2: PRM-01 (VÍ DỤ) | B2: L01-G4-01 | C2: L01 | D2: Bùi Hiếu Nhân | E2: Claude 3.5 Sonnet | F2: v1.0 | G2: docs/flows/L01-quiz-routine/flow-card.md | H2: Dựa trên Flow Card L01 và cấu trúc bảng wp_options, hãy sinh class Quiz_Engine xử lý tính điểm weighted tag matching... | I2: Cần sửa | J2: Thiếu kiểm tra nonce CSRF trong REST endpoint, đã bổ sung tay trước khi mở PR | K2: https://github.com/QuocAn0303/KLEER/pull/12 | L2: 46307

Sheet Mẫu Prompt
A1: HƯỚNG DẪN SỬ DỤNG MẪU PROMPT CHO AI AGENT
A2: 1. Đọc kỹ Flow Card và sơ đồ đã được PO/SM duyệt tại cổng G3 trước khi điền thông tin.
A3: 2. Thay thế toàn bộ các phần trong ngoặc vuông [...] bằng đặc tả chi tiết của module cần sinh code.
A4: 3. Không tự ý chỉnh sửa các ràng buộc tại mục 'KHÔNG ĐƯỢC LÀM' để bảo đảm tính kỷ luật của repo.
A6: # BỐI CẢNH Dự án KLEER: website TMĐT mỹ phẩm Unisex trên WordPress/WooCommerce, chạy Docker (nginx, php 8.2-fpm, mariadb 10.11, redis). Theme: wp-content/themes/kleer-theme/. Plugin: wp-content/plugins/kleer-plugin/. Không sửa WordPress Core. Không dùng Elementor/WPBakery. Chuẩn code: PHP theo PSR-12, JS ES6+. Mọi thay đổi qua Pull Request vào nhánh develop. # LUỒNG VÀ NHIỆM VỤ Luồng: [Lxx – tên luồng] Nhiệm vụ cụ thể (1 việc, 1 đầu ra): [mô tả] # ĐẦU VÀO (đính kèm hoặc dán vào) - Flow Card: [link/nội dung] - Sơ đồ: [link/mermaid] - Endpoint/Hook đã chốt: [request/response mẫu] - Dữ liệu liên quan: [bảng, meta, taxonomy] # ĐẦU RA MONG ĐỢI - Danh sách file cần tạo/sửa (đường dẫn đầy đủ) - Hàm/class/hook chính và chữ ký - Cách chạy thử trong Docker # TIÊU CHÍ CHẤP NHẬN (Given–When–Then) [≥ 5 ca, gồm ≥ 2 ca ngoại lệ] # KHÔNG ĐƯỢC LÀM - Không sửa file ngoài phạm vi nêu trên - Không commit .env, secret - Không thêm thư viện mới nếu chưa hỏi # YÊU CẦU CUỐI Liệt kê các giả định đã dùng và những chỗ cần người review kiểm tra kỹ.

Sheet Cần chốt
A1: STT | B1: Vấn đề | C1: Phương án mặc định | D1: Ai chốt | E1: Hạn chốt | F1: Trạng thái
A2: 1 | B2: Tên thư mục và REST namespace | C2: Sổ tay dùng unisex-theme và unisex-quiz-engine nhưng repo dùng kleer-theme và kleer-plugin. Mặc định: theo repo cho thư mục; namespace REST cần chốt trước khi Nhân viết endpoint (Tuần 7). giữ kleer/v1 | D2: Lê Nguyễn Quốc An | E2: 46327 | F2: Đã chốt
A3: 2 | B3: Phạm vi L06 Giao hàng | C3: Mặc định mô phỏng bằng trạng thái đơn tùy biến (Đóng gói, Đang giao, Đã giao, Giao thất bại), chưa tích hợp API hãng vận chuyển để tránh quá tải. | D3: Lê Nguyễn Quốc An + Nguyễn Tấn Phát | E3: 46313 | F3: Đã thống nhất sơ bộ
A4: 3 | B4: Phạm vi L07 Hoàn tiền | C4: Mặc định dùng refund có sẵn của WooCommerce và nhập lại kho; chưa gọi API hoàn tiền của VNPay Sandbox. | D4: Nguyễn Tấn Phát + Trần Ngọc Minh Tuyền | E4: 46313 | F4: Đã thống nhất sơ bộ
A5: 4 | B5: Chính sách đổi trả 7 ngày | C5: 7 ngày tính từ ngày "Đã giao" hay ngày đặt hàng? Điều kiện hàng trả (chưa mở seal, lỗi nhà sản xuất)? | D5: Nguyễn Tấn Phát | E5: 46320 | F5: Đang chờ
A6: 5 | B6: Danh sách trạng thái đơn hàng chuẩn | C6: Cần định nghĩa danh sách trạng thái chuẩn gồm cả trạng thái đổi trả và giao hàng để đồng bộ HPOS. | D6: Nguyễn Tấn Phát + Nguyễn Minh Trí | E6: 46313 | F6: Đang chờ
A7: 6 | B7: Combo subscription (nhắc trong Lean Canvas) | C7: Có làm không? Mặc định: không làm (Could) để tập trung vào luồng cốt lõi. | D7: Nguyễn Tấn Phát | E7: 46306 | F7: Đã thống nhất bỏ qua
A8: 7 | B8: Tên thương hiệu dùng trong báo cáo và domain | C8: KLEER hay "Unisex Skincare"? Mặc định chọn KLEER làm tên thương hiệu thương mại. | D8: Nguyễn Tấn Phát + Lê Nguyễn Quốc An | E8: 46306 | F8: Đã chọn KLEER
A9: 8 | B9: Trạng thái Tuần 6 trong sheet cũ | C9: Trạng thái (Đang thực hiện/Đang review) nhìn như dữ liệu mẫu, đã đặt lại về Backlog trong hệ thống mới. | D9: Lê Nguyễn Quốc An | E9: 46299 | F9: Đã chốt về Backlog
A10: 9 | B10: Quy ước viết prompt cho AI agent | C10: Ai được dùng agent nào, bắt buộc ghi Prompt Log cho mọi prompt sinh code hay chỉ với module chính. | D10: Lê Nguyễn Quốc An | E10: 46306 | F10: Đang chờ

Sheet Đối chiếu task cũ
A1: Mã cũ | B1: Tuần cũ | C1: Thành viên cũ | D1: Tóm tắt cũ | E1: DoD cũ | F1: Trạng thái cũ | G1: Mã task mới tương ứng | H1: Luồng | I1: Ghi chú tách/gộp | J1: Đã map?
A2: TASK-01 | B2: Tuần 01 | C2: Nguyễn Tấn Phát | D2: Khảo sát thị trường Unisex Skincare, phân tích chân dung khách hàng Gen Z và người bận rộn; Viết đề cương chi tiết Chương 1 Báo cáo (Lý do chọn đề tài, mục tiêu, phạm vi). | E2: Bản thảo Chương 1 file Word (tối thiểu 3 trang), có số liệu thị trường kèm trích dẫn nguồn uy tín. | F2: Đang thực hiện | G2: L00-G1-01 | H2: L00 | I2: Chuyển thành task G1 nghiên cứu thị trường của luồng Quản trị L00 | J2: =IF(COUNTIF(Tasks!$S$2:$S$137,"*"&A2&"*")>0,"ĐÃ MAP","CHƯA MAP") -> #ERROR!
A3: TASK-02 | B3: Tuần 01 | C3: Lê Nguyễn Quốc An | D3: Khởi tạo GitHub repo, cấu hình nhánh main/develop, branch protection; Viết docker-compose.yml chuẩn (Nginx, PHP 8.2-FPM, MariaDB 10.11, Redis, phpMyAdmin). | E3: 100% 8 thành viên khởi động thành công web local qua Docker trong 1 lệnh không lỗi port/môi trường. | F3: Hoàn thành | G3: L09-G5-01 | H3: L09 | I3: Chuyển thành task G5 khởi tạo Docker stack của luồng Hạ tầng L09 (Rubric 5.1) | J3: =IF(COUNTIF(Tasks!$S$2:$S$137,"*"&A3&"*")>0,"ĐÃ MAP","CHƯA MAP") -> #ERROR!
A4: TASK-03 | B4: Tuần 01 | C4: Bùi Hiếu Nhân | D4: Nghiên cứu cấu trúc phát triển Plugin WordPress OOP Boilerplate; Lập kế hoạch kiến trúc thư mục Custom Plugin tách biệt hoàn toàn khỏi Theme. | E4: Tài liệu cấu trúc Plugin: Tách biệt rõ Controllers, Models, Services và Endpoints. | F4: Hoàn thành | G4: L09-G1-01 | H4: L09 | I4: Chuyển thành task G1 nghiên cứu kiến trúc Custom Plugin OOP Boilerplate | J4: =IF(COUNTIF(Tasks!$S$2:$S$137,"*"&A4&"*")>0,"ĐÃ MAP","CHƯA MAP") -> #ERROR!
A5: TASK-04 | B5: Tuần 01 | C5: Trần Ngọc Minh Tuyền | D5: Nghiên cứu tài liệu kỹ thuật tích hợp cổng thanh toán trực tuyến tại Việt Nam (VNPay Sandbox, Momo Sandbox, COD, VietQR); Đăng ký tài khoản Sandbox. | E5: Tài khoản VNPay/Momo Sandbox được kích hoạt, có đầy đủ TmnCode và HashSecret. | F5: Đang thực hiện | G5: L04-G1-01 | H5: L04 | I5: Chuyển thành task G1 nghiên cứu cổng thanh toán Sandbox của luồng Checkout L04 (Rubric 5.2) | J5: =IF(COUNTIF(Tasks!$S$2:$S$137,"*"&A5&"*")>0,"ĐÃ MAP","CHƯA MAP") -> #ERROR!
A6: TASK-05 | B6: Tuần 01 | C6: Lâm Trúc Uyên | D6: Nghiên cứu phong cách thiết kế Unisex Skincare (Minimalist, tone màu Earthy Tone, font sans-serif); Tạo Moodboard và Design Tokens. | E6: Bảng Design Guidelines (PDF/Figma link) được PO và nhóm thống nhất thông qua. | F6: Hoàn thành | G6: L02-G1-01 | H6: L02 | I6: Chuyển thành task G1 nghiên cứu phong cách thiết kế Unisex Skincare của luồng Catalog L02 | J6: =IF(COUNTIF(Tasks!$S$2:$S$137,"*"&A6&"*")>0,"ĐÃ MAP","CHƯA MAP") -> #ERROR!
A7: TASK-06 | B7: Tuần 01 | C7: Huỳnh Ngọc Nhã Uyên | D7: Nghiên cứu cơ chế tương tác (Micro-interactions) của Quiz mỹ phẩm hàng đầu (Curology, Function of Beauty, Sephora); Lên ý tưởng trải nghiệm UX. | E7: Bản phân tích UX Benchmark kèm đề xuất hiệu ứng chuyển cảnh cho đồ án. | F7: Hoàn thành | G7: L01-G1-01 | H7: L01 | I7: Chuyển thành task G1 nghiên cứu UX Benchmark Quiz của luồng Quiz L01 | J7: =IF(COUNTIF(Tasks!$S$2:$S$137,"*"&A7&"*")>0,"ĐÃ MAP","CHƯA MAP") -> #ERROR!
A8: TASK-07 | B8: Tuần 01 | C8: Nguyễn Ngọc Thảo Uyên | D8: Xây dựng Test Plan tổng thể cho dự án: Phạm vi, chiến lược kiểm thử, định nghĩa Severity (Critical, Major, Minor); Thiết lập Bug Report template trên GitHub Issues. | E8: Tài liệu Test Plan hoàn chỉnh; mẫu GitHub Issue Template cho Bug Report hoạt động. | F8: Hoàn thành | G8: L10-G1-01 | H8: L10 | I8: Chuyển thành task G1 xây dựng Test Plan tổng thể của luồng Tự động hóa L10 | J8: =IF(COUNTIF(Tasks!$S$2:$S$137,"*"&A8&"*")>0,"ĐÃ MAP","CHƯA MAP") -> #ERROR!
A9: TASK-08 | B9: Tuần 01 | C9: Nguyễn Minh Trí | D9: Phân tích cấu trúc HTML các website mỹ phẩm uy tín (Hasaki, Cocoon, Paula's Choice); Lựa chọn giải pháp kỹ thuật viết Web Crawler (Python BeautifulSoup/Playwright). | E9: Tài liệu phân tích cấu trúc DOM trang nguồn và script thử nghiệm lấy được 5 sản phẩm mẫu. | F9: Hoàn thành | G9: L08-G1-01 | H9: L08 | I9: Chuyển thành task G1 phân tích DOM website nguồn của luồng Dữ liệu L08 (Rubric 5.4) | J9: =IF(COUNTIF(Tasks!$S$2:$S$137,"*"&A9&"*")>0,"ĐÃ MAP","CHƯA MAP") -> #ERROR!
A10: TASK-09 | B10: Tuần 02 | C10: Nguyễn Tấn Phát | D10: Lập Lean Canvas, xác định mô hình doanh thu B2C (bán lẻ + combo subscription); Phân tích SWOT hệ thống với 4 chiến lược kết hợp (SO, WO, ST, WT). | E10: Hoàn thiện Chương 1 & 2 file Báo cáo; ma trận SWOT có ít nhất 4 yếu tố trên mỗi góc phân tích. | F10: Chưa bắt đầu | G10: L00-G1-02 | H10: L00 | I10: Chuyển thành task G1 lập Lean Canvas & SWOT của luồng Quản trị L00 | J10: =IF(COUNTIF(Tasks!$S$2:$S$137,"*"&A10&"*")>0,"ĐÃ MAP","CHƯA MAP") -> #ERROR!
A11: TASK-10 | B11: Tuần 02 | C11: Lê Nguyễn Quốc An | D11: Thiết lập Kanban Board trên Trello/Notion, tạo các cột trạng thái; Vận hành nghi thức Daily Async Standup hằng ngày lúc 22:00. | E11: Bảng quản lý công việc trực tuyến hoạt động; 100% thành viên cập nhật báo cáo tiến độ đúng giờ. | F11: Đang thực hiện | G11: L00-G1-03 | H11: L00 | I11: Chuyển thành task G1 thiết lập Kanban Board & Daily Standup của luồng Quản trị L00 | J11: =IF(COUNTIF(Tasks!$S$2:$S$137,"*"&A11&"*")>0,"ĐÃ MAP","CHƯA MAP") -> #ERROR!
A12: TASK-11 | B12: Tuần 02 | C12: Bùi Hiếu Nhân | D12: Khởi tạo Custom Plugin trong thư mục /wp-content/plugins/unisex-quiz-engine/; Thiết lập cơ chế kích hoạt (Activation Hook), hủy kích hoạt (Deactivation Hook) và autoloader. | E12: Plugin kích hoạt an toàn trong WP-Admin mà không sinh lỗi PHP Warning/Notice. | F12: Chưa bắt đầu | G12: L01-G5-01 | H12: L01 | I12: Chuyển thành task G5 khởi tạo kleer-plugin với activation/deactivation hooks của luồng Quiz L01 | J12: =IF(COUNTIF(Tasks!$S$2:$S$137,"*"&A12&"*")>0,"ĐÃ MAP","CHƯA MAP") -> #ERROR!
A13: TASK-12 | B13: Tuần 02 | C13: Trần Ngọc Minh Tuyền | D13: Cấu hình phương thức thanh toán truyền thống trong WooCommerce: Thanh toán khi nhận hàng (COD) và Chuyển khoản ngân hàng (BACS) với mã VietQR tự sinh theo số tiền đơn. | E13: Khách hàng có thể chọn COD hoặc quét mã VietQR thành công ở màn hình Thank You page. | F13: Chưa bắt đầu | G13: L04-G5-01 | H13: L04 | I13: Chuyển thành task G5 cấu hình phương thức thanh toán COD & VietQR của luồng Checkout L04 (Rubric 5.2) | J13: =IF(COUNTIF(Tasks!$S$2:$S$137,"*"&A13&"*")>0,"ĐÃ MAP","CHƯA MAP") -> #ERROR!
... A81: TASK-80 | B81: Tuần 10 | C81: Nguyễn Minh Trí | D81: Đóng gói toàn bộ mã nguồn script Crawler vào repository kèm requirements.txt; Viết mục báo cáo kỹ thuật về Web Crawler (Mục 5.4) và Tối ưu HPOS/Redis. | E81: Mục 5.4 trong báo cáo đầy đủ mã nguồn, hình ảnh minh chứng quá trình cào dữ liệu đúng Rubric. | F81: Chưa bắt đầu | G81: L08-G8-01 | H81: L08 | I81: Chuyển thành task G8 đóng gói script Crawler repo & báo cáo 5.4 của luồng Dữ liệu L08 (Rubric 5.4) | J81: =IF(COUNTIF(Tasks!$S$2:$S$137,"*"&A81&"*")>0,"ĐÃ MAP","CHƯA MAP") -> #ERROR!

Sheet Tasks
A1: Mã task | B1: Luồng | C1: Cổng | D1: Tên việc | E1: Mô tả chi tiết | F1: Đầu vào cần có | G1: Sản phẩm bàn giao | H1: Thư mục Drive quy định | I1: Tên file bản vẽ chuẩn (.drawio/Figma) | J1: Quy tắc & Prompt Rule (Ràng buộc AI) | K1: DoD (đo được) | L1: Người thực hiện | M1: Vai trò | N1: Người duyệt | O1: Tuần | P1: Bắt đầu | Q1: Hạn | R1: Phụ thuộc | S1: Ưu tiên | T1: Trạng thái | U1: Rubric | V1: Mã task cũ | W1: Link bàn giao (PR / Drive / Figma) | X1: Ghi chú | Y1: Cảnh báo
A2: L02-G1-01 | B2: L02 | C2: G1 | D2: Nghiên cứu phong cách thiết kế Unisex Skincare (Minimalist, tone màu Earthy Tone, font sans-serif); Tạo Moodboard và Design Tokens (màu sắc, typography, spacing). | E2: Nghiên cứu phong cách thiết kế Unisex Skincare (Minimalist, tone màu Earthy Tone, font sans-serif); Tạo Moodboard và Design Tokens (màu sắc, typography, spacing). | F2: Tài liệu yêu cầu dự án và dữ liệu từ các luồng liên quan | G2: Bảng Design Guidelines (PDF/Figma link) được PO và nhóm thống nhất thông qua. | H2: Thiết kế hệ thống TMDT/Trúc Uyên/ | I2: [NGƯỜI THIẾT KẾ] Figma: KLEER - Design System & Catalog PDP Wireframe | J2: Phong cách Minimalist Earthy Tone; Sans-serif; Đầy đủ Desktop 1440px và Mobile 375px; Tự dán link Figma frame vào ô này. | K2: Bảng Design Guidelines (PDF/Figma link) được PO và nhóm thống nhất thông qua. | L2: Lâm Trúc Uyên | M2: Theme Dev 1 (Catalog, UI) | N2: Lê Nguyễn Quốc An | O2: Tuần 01 | P2: =VLOOKUP(O2,'Danh mục'!$A$3:$D$12,2,FALSE) -> #N/A | Q2: =VLOOKUP(O2,'Danh mục'!$A$3:$D$12,3,FALSE) -> #N/A | S2: Cao | T2: Done | U2: Không | V2: TASK-05 | W2: https://www.figma.com/design/BaI9IvT2Mji4nBZ3n6FKFH/Design-system?node-id=49-4&t=2m2RM9qCQVkipAsD-1 | Y2: =IF(AND(TODAY()>Q2,T2<>"Done"),"TRỄ",IF(AND(C2="G4",VLOOKUP(B2,DoR!$A$2:$K$12,11,FALSE)<>"SẴN SÀNG PROMPT"),"THIẾU ĐẦU VÀO","")) -> #N/A
A3: L04-G1-01 | B3: L04 | C3: G1 | D3: Nghiên cứu tài liệu kỹ thuật tích hợp cổng thanh toán trực tuyến tại Việt Nam (VNPay Sandbox, Momo Sandbox, COD, VietQR); Đăng ký tài khoản Sandbox. | E3: Nghiên cứu tài liệu kỹ thuật tích hợp cổng thanh toán trực tuyến tại Việt Nam (VNPay Sandbox, Momo Sandbox, COD, VietQR); Đăng ký tài khoản Sandbox. | F3: Tài liệu yêu cầu dự án và dữ liệu từ các luồng liên quan | G3: Tài khoản VNPay/Momo Sandbox được kích hoạt, có đầy đủ TmnCode và HashSecret. | H3: Thiết kế hệ thống TMDT/Minh Tuyền/ | K3: Tài khoản VNPay/Momo Sandbox được kích hoạt, có đầy đủ TmnCode và HashSecret. | L3: Trần Ngọc Minh Tuyền | M3: Integration Dev (thanh toán, email, vận chuyển, REST API) | N3: Lê Nguyễn Quốc An | O3: Tuần 01 | P3: =VLOOKUP(O3,'Danh mục'!$A$3:$D$12,2,FALSE) -> #N/A | Q3: =VLOOKUP(O3,'Danh mục'!$A$3:$D$12,3,FALSE) -> #N/A | S3: Trung bình | T3: In Progress | U3: 46058 | V3: TASK-04 | X3: Doc v1.0 | Y3: =IF(AND(TODAY()>Q3,T3<>"Done"),"TRỄ",IF(AND(C3="G4",VLOOKUP(B3,DoR!$A$2:$K$12,11,FALSE)<>"SẴN SÀNG PROMPT"),"THIẾU ĐẦU VÀO","")) -> #N/A
A4: L01-G2-01 | B4: L01 | C4: G2 | D4: Thiết kế Prototype UI và kịch bản luồng Quiz Flowchart | E4: Thiết kế Figma Prototype chi tiết từng câu hỏi có thanh tiến trình và vẽ sơ đồ luồng Quiz Flowchart dạng khối. | F4: Tài liệu yêu cầu dự án và dữ liệu từ các luồng liên quan | G4: Figma Interactive Prototype: Thao tác click chọn đáp án và chuyển màn hình trực quan, được PO duyệt. | H4: Thiết kế hệ thống TMDT/Nhã Uyên/ | I4: [NGƯỜI VẼ] L01_Quiz_Logic_Flowchart.drawio (và Figma: KLEER - Quiz SPA UI) | J4: Vẽ sơ đồ khối rẽ nhánh câu hỏi và ma trận tính điểm 4 bước; Bắt buộc ném file gốc .drawio/Figma vào Drive; Tuyệt đối cấm chụp ảnh màn hình; Tự dán link file vào ô này sau khi up. | K4: Figma Interactive Prototype thao tác mượt mà và sơ đồ luồng Quiz xác định rõ các rẽ nhánh điều kiện. | L4: Huỳnh Ngọc Nhã Uyên | M4: Theme Dev 2 (Quiz Frontend, Cart/Checkout UX) | N4: Lê Nguyễn Quốc An | O4: Tuần 02 | P4: =VLOOKUP(O4,'Danh mục'!$A$3:$D$12,2,FALSE) -> 46293 | Q4: =VLOOKUP(O4,'Danh mục'!$A$3:$D$12,3,FALSE) -> 46299 | S4: Cao | T4: To Do | U4: Không | V4: TASK-14, TASK-25 | Y4: =IF(AND(TODAY()>Q4,T4<>"Done"),"TRỄ",IF(AND(C4="G4",VLOOKUP(B4,DoR!$A$2:$K$12,11,FALSE)<>"SẴN SÀNG PROMPT"),"THIẾU ĐẦU VÀO","")) -> TRỄ
A5: L01-G5-01 | B5: L01 | C5: G5 | D5: Khởi tạo Custom Plugin trong thư mục /wp-content/plugins/unisex-quiz-engine/; Thiết lập cơ chế kích hoạt (Activation Hook), hủy kích hoạt (Deactivation Hook) và autoloader. | E5: Khởi tạo Custom Plugin trong thư mục /wp-content/plugins/unisex-quiz-engine/; Thiết lập cơ chế kích hoạt (Activation Hook), hủy kích hoạt (Deactivation Hook) và autoloader. | F5: Tài liệu yêu cầu dự án và dữ liệu từ các luồng liên quan | G5: Plugin kích hoạt an toàn trong WP-Admin mà không sinh lỗi PHP Warning/Notice. | H5: Thiết kế hệ thống TMDT/Hiếu Nhân/ | I5: [CODE ĐỘC LẬP - Không phụ thuộc bản vẽ] | J5: Khởi tạo Custom Plugin boilerplate trong /wp-content/plugins/unisex-quiz-engine/; Activation/Deactivation hooks; PSR-4 Autoloader. | K5: Plugin kích hoạt an toàn trong WP-Admin mà không sinh lỗi PHP Warning/Notice. | L5: Bùi Hiếu Nhân | M5: Plugin Dev 1 (Quiz Backend, Taxonomy, REST) | N5: Lê Nguyễn Quốc An | O5: Tuần 02 | P5: =VLOOKUP(O5,'Danh mục'!$A$3:$D$12,2,FALSE) -> 46293 | Q5: =VLOOKUP(O5,'Danh mục'!$A$3:$D$12,3,FALSE) -> 46299 | S5: Cao | T5: To Do | U5: Không | V5: TASK-11 | Y5: =IF(AND(TODAY()>Q5,T5<>"Done"),"TRỄ",IF(AND(C5="G4",VLOOKUP(B5,DoR!$A$2:$K$12,11,FALSE)<>"SẴN SÀNG PROMPT"),"THIẾU ĐẦU VÀO","")) -> TRỄ
A6: L02-G2-01 | B6: L02 | C6: G2 | D6: Thiết kế Wireframe và Mockup UI chi tiết trên Figma cho: Trang chủ, Trang danh mục (Catalog), Trang chi tiết sản phẩm (PDP). Chuẩn Responsive Mobile-first. | E6: Thiết kế Wireframe và Mockup UI chi tiết trên Figma cho: Trang chủ, Trang danh mục (Catalog), Trang chi tiết sản phẩm (PDP). Chuẩn Responsive Mobile-first. | F6: Tài liệu yêu cầu dự án và dữ liệu từ các luồng liên quan | G6: Figma Prototype hoàn chỉnh cả 2 phiên bản Desktop và Mobile được PO phê duyệt. | H6: Thiết kế hệ thống TMDT/Trúc Uyên/ | I6: [NGƯỜI THIẾT KẾ] Figma: KLEER - Design System & Catalog PDP Wireframe | J6: Phong cách Minimalist Earthy Tone; Sans-serif; Đầy đủ Desktop 1440px và Mobile 375px; Tự dán link Figma frame vào ô này. | K6: Figma Prototype hoàn chỉnh cả 2 phiên bản Desktop và Mobile được PO phê duyệt. | L6: Lâm Trúc Uyên | M6: Theme Dev 1 (Catalog, UI) | N6: Lê Nguyễn Quốc An | O6: Tuần 02 | P6: =VLOOKUP(O6,'Danh mục'!$A$3:$D$12,2,FALSE) -> 46293 | Q6: =VLOOKUP(O6,'Danh mục'!$A$3:$D$12,3,FALSE) -> 46299 | S6: Cao | T6: In Progress | U6: Không | V6: TASK-13 | Y6: =IF(AND(TODAY()>Q6,T6<>"Done"),"TRỄ",IF(AND(C6="G4",VLOOKUP(B6,DoR!$A$2:$K$12,11,FALSE)<>"SẴN SÀNG PROMPT"),"THIẾU ĐẦU VÀO","")) -> TRỄ
A7: L03-G1-01 | B7: L03 | C7: G1 | D7: Viết Flow Card luồng Giỏ hàng và tính năng giảm 15% Combo Routine | E7: Đặc tả chi tiết Flow Card cho Giỏ hàng tại docs/flows/L03-cart-combo/flow-card.md, cơ chế thêm 1-click Routine và kiểm tra xung đột hoạt chất. | F7: Quy tắc kinh doanh Combo Skincare từ PO | G7: File docs/flows/L03-cart-combo/flow-card.md hoàn chỉnh | H7: Thiết kế hệ thống TMDT/Nhã Uyên/ | K7: Flow Card nêu rõ công thức tự động trừ 15% khi đủ 3-4 bước Routine và cảnh báo xung đột AHA/Retinol. | L7: Huỳnh Ngọc Nhã Uyên | M7: Theme Dev 2 (Quiz Frontend, Cart/Checkout UX) | N7: Nguyễn Tấn Phát | O7: Tuần 02 | P7: =VLOOKUP(O7,'Danh mục'!$A$3:$D$12,2,FALSE) -> 46293 | Q7: =VLOOKUP(O7,'Danh mục'!$A$3:$D$12,3,FALSE) -> 46299 | R7: TASK-06 | S7: Cao | T7: To Do | U7: Không | Y7: =IF(AND(TODAY()>Q7,T7<>"Done"),"TRỄ",IF(AND(C7="G4",VLOOKUP(B7,DoR!$A$2:$K$12,11,FALSE)<>"SẴN SÀNG PROMPT"),"THIẾU ĐẦU VÀO","")) -> TRỄ
A8: L04-G5-01 | B8: L04 | C8: G5 | D8: Cấu hình phương thức thanh toán truyền thống trong WooCommerce: Thanh toán khi nhận hàng (COD) và Chuyển khoản ngân hàng (BACS) với mã VietQR tự sinh theo số tiền đơn. | E8: Cấu hình phương thức thanh toán truyền thống trong WooCommerce: Thanh toán khi nhận hàng (COD) và Chuyển khoản ngân hàng (BACS) với mã VietQR tự sinh theo số tiền đơn. | F8: Tài liệu yêu cầu dự án và dữ liệu từ các luồng liên quan | G8: Khách hàng có thể chọn COD hoặc quét mã VietQR thành công ở màn hình Thank You page. | H8: Thiết kế hệ thống TMDT/Minh Tuyền/ | I8: [CODE ĐỘC LẬP - Không phụ thuộc bản vẽ] | J8: Cấu hình COD chuẩn WooCommerce; Tích hợp BACS VietQR tự sinh mã theo số tiền và cú pháp đơn hàng. | K8: Khách hàng có thể chọn COD hoặc quét mã VietQR thành công ở màn hình Thank You page. | L8: Trần Ngọc Minh Tuyền | M8: Integration Dev (thanh toán, email, vận chuyển, REST API) | N8: Lê Nguyễn Quốc An | O8: Tuần 02 | P8: =VLOOKUP(O8,'Danh mục'!$A$3:$D$12,2,FALSE) -> 46293 | Q8: =VLOOKUP(O8,'Danh mục'!$A$3:$D$12,3,FALSE) -> 46299 | S8: Cao | T8: To Do | U8: 46058 | V8: TASK-12 | Y8: =IF(AND(TODAY()>Q8,T8<>"Done"),"TRỄ",IF(AND(C8="G4",VLOOKUP(B8,DoR!$A$2:$K$12,11,FALSE)<>"SẴN SÀNG PROMPT"),"THIẾU ĐẦU VÀO","")) -> TRỄ
A9: L05-G1-01 | B9: L05 | C9: G1 | D9: Viết Flow Card vòng đời xử lý đơn hàng và lưu trữ HPOS | E9: Đặc tả Flow Card tại docs/flows/L05-order-processing/flow-card.md cho vòng đời đơn từ Chờ thanh toán -> Đang xử lý -> Sẵn sàng giao, kiến trúc bảng HPOS. | F9: Tài liệu kỹ thuật WooCommerce HPOS và cấu trúc CSDL | G9: File docs/flows/L05-order-processing/flow-card.md hoàn chỉnh | H9: Thiết kế hệ thống TMDT/Minh Trí/ | K9: Flow Card xác định rõ 5 trạng thái đơn chuẩn, cơ chế trừ kho tự động và trigger gửi email hóa đơn. | L9: Nguyễn Minh Trí | M9: Plugin Dev 2 (Crawler, HPOS, Redis, khuyến mãi) | N9: Lê Nguyễn Quốc An | O9: Tuần 02 | P9: =VLOOKUP(O9,'Danh mục'!$A$3:$D$12,2,FALSE) -> 46293 | Q9: =VLOOKUP(O9,'Danh mục'!$A$3:$D$12,3,FALSE) -> 46299 | R9: TASK-08 | S9: Cao | T9: To Do | U9: 46086 | Y9: =IF(AND(TODAY()>Q9,T9<>"Done"),"TRỄ",IF(AND(C9="G4",VLOOKUP(B9,DoR!$A$2:$K$12,11,FALSE)<>"SẴN SÀNG PROMPT"),"THIẾU ĐẦU VÀO","")) -> TRỄ
A10: L05-G7-01 | B10: L05 | C10: G7 | D10: Xây dựng Test Cases cho các chức năng cơ bản của WooCommerce: Đăng ký/Đăng nhập, thêm sản phẩm vào giỏ, nhập mã giảm giá, đặt hàng COD. | E10: Xây dựng Test Cases cho các chức năng cơ bản của WooCommerce: Đăng ký/Đăng nhập, thêm sản phẩm vào giỏ, nhập mã giảm giá, đặt hàng COD. | F10: Tài liệu yêu cầu dự án và dữ liệu từ các luồng liên quan | G10: Bộ 25 Test Cases chi tiết cho phân hệ người dùng và thanh toán chuẩn. | H10: Thiết kế hệ thống TMDT/Thảo Uyên/ | K10: Bộ 25 Test Cases chi tiết cho phân hệ người dùng và thanh toán chuẩn. | L10: Nguyễn Ngọc Thảo Uyên | M10: QA & Automation (Selenium) | N10: Lê Nguyễn Quốc An | O10: Tuần 02 | P10: =VLOOKUP(O10,'Danh mục'!$A$3:$D$12,2,FALSE) -> 46293 | Q10: =VLOOKUP(O10,'Danh mục'!$A$3:$D$12,3,FALSE) -> 46299 | S10: Cao | T10: To Do | U10: 46086 | V10: TASK-15 | W10: 25 Test Case | Y10: =IF(AND(TODAY()>Q10,T10<>"Done"),"TRỄ",IF(AND(C10="G4",VLOOKUP(B10,DoR!$A$2:$K$12,11,FALSE)<>"SẴN SÀNG PROMPT"),"THIẾU ĐẦU VÀO","")) -> TRỄ
A11: L01-G3-01 | B11: L01 | C11: G3 | D11: Phê duyệt nghiệp vụ và kỹ thuật luồng Quiz chẩn đoán da L01 | E11: Rà soát tính nhất quán giữa Flow Card, ma trận trọng số và sơ đồ luồng Quiz để cấp quyền chuyển sang cổng Prompt Agent. | F11: Flow Card L01, Quiz Flowchart và ma trận câu hỏi | G11: Biên bản phê duyệt G3 tại docs/flows/L01-quiz-routine/approval.md | H11: Thiết kế hệ thống TMDT/Hiếu Nhân/ | K11: PO Phát và SM An xác nhận đạt 8/8 tiêu chí DoR, trạng thái luồng L01 chuyển thành SẴN SÀNG PROMPT. | L11: Bùi Hiếu Nhân | M11: Plugin Dev 1 (Quiz Backend, Taxonomy, REST) | N11: Nguyễn Tấn Phát | O11: Tuần 03 | P11: =VLOOKUP(O11,'Danh mục'!$A$3:$D$12,2,FALSE) -> 46300 | Q11: =VLOOKUP(O11,'Danh mục'!$A$3:$D$12,3,FALSE) -> 46306 | R11: L01-G1-03 | S11: Khẩn cấp | T11: Backlog | U11: Không | Y11: =IF(AND(TODAY()>Q11,T11<>"Done"),"TRỄ",IF(AND(C11="G4",VLOOKUP(B11,DoR!$A$2:$K$12,11,FALSE)<>"SẴN SÀNG PROMPT"),"THIẾU ĐẦU VÀO","")) -> TRỄ
A12: L01-G5-02 | B12: L01 | C12: G5 | D12: Lập trình SPA Quiz Frontend bằng HTML5 semantic và Vanilla JS | E12: Dựng template HTML5 và viết script SPA Quiz Vanilla JS không reload trang, lưu state tạm vào LocalStorage/State. | F12: Tài liệu yêu cầu dự án và dữ liệu từ các luồng liên quan | G12: Template tĩnh hoàn chỉnh cho từng câu hỏi, hiển thị đúng tỷ lệ trên cả Desktop và Mobile. | H12: Thiết kế hệ thống TMDT/Nhã Uyên/ | I12: [TỰ VẼ TỰ CODE] Lấy từ bản vẽ L01-G2-01 của chính mình | J12: Vanilla JS SPA; 100% không reload trang; Fetch API gửi answers sang backend; Render Routine kết quả responsive mobile-first. | K12: Template tĩnh hoàn chỉnh và Quiz hoạt động 100% không reload trang; thanh tiến trình cập nhật mượt mà. | L12: Huỳnh Ngọc Nhã Uyên | M12: Theme Dev 2 (Quiz Frontend, Cart/Checkout UX) | N12: Lê Nguyễn Quốc An | O12: Tuần 03 | P12: =VLOOKUP(O12,'Danh mục'!$A$3:$D$12,2,FALSE) -> 46300 | Q12: =VLOOKUP(O12,'Danh mục'!$A$3:$D$12,3,FALSE) -> 46306 | S12: Trung bình | T12: Backlog | U12: Không | V12: TASK-22, TASK-30 | Y12: =IF(AND(TODAY()>Q12,T12<>"Done"),"TRỄ",IF(AND(C12="G4",VLOOKUP(B12,DoR!$A$2:$K$12,11,FALSE)<>"SẴN SÀNG PROMPT"),"THIẾU ĐẦU VÀO","")) -> TRỄ
A13: L01-G7-01 | B13: L01 | C13: G7 | D13: Soạn thảo Ma trận Kiểm thử Quiz và thực thi kiểm thử trên bản tích hợp | E13: Liệt kê 30 ca kiểm thử Quiz và thực thi toàn bộ Ma trận kiểm thử trên phiên bản tích hợp giữa Frontend và Backend. | F13: Tài liệu yêu cầu dự án và dữ liệu từ các luồng liên quan | G13: Bảng Ma trận kiểm thử Quiz gồm ít nhất 30 ca kiểm thử (Test Scenarios). | H13: Thiết kế hệ thống TMDT/Thảo Uyên/ | K13: Bảng Ma trận kiểm thử Quiz gồm ít nhất 30 ca; 100% tổ hợp Quiz test thành công, không bị lỗi trang trắng. | L13: Nguyễn Ngọc Thảo Uyên | M13: QA & Automation (Selenium) | N13: Lê Nguyễn Quốc An | O13: Tuần 03 | P13: =VLOOKUP(O13,'Danh mục'!$A$3:$D$12,2,FALSE) -> 46300 | Q13: =VLOOKUP(O13,'Danh mục'!$A$3:$D$12,3,FALSE) -> 46306 | S13: Cao | T13: Backlog | U13: Không | V13: TASK-23, TASK-47 | W13: ma trận kiểm thử Quiz | Y13: =IF(AND(TODAY()>Q13,T13<>"Done"),"TRỄ",IF(AND(C13="G4",VLOOKUP(B13,DoR!$A$2:$K$12,11,FALSE)<>"SẴN SÀNG PROMPT"),"THIẾU ĐẦU VÀO","")) -> TRỄ
A14: L02-G5-01 | B14: L02 | C14: G5 | D14: Khởi tạo Custom Theme trong thư mục /wp-content/themes/unisex-theme/; Thiết lập functions.php, style.css, enqueue các file CSS/JS nền tảng. | E14: Khởi tạo Custom Theme trong thư mục /wp-content/themes/unisex-theme/; Thiết lập functions.php, style.css, enqueue các file CSS/JS nền tảng. | F14: Tài liệu yêu cầu dự án và dữ liệu từ các luồng liên quan | G14: Theme kích hoạt thành công trên WordPress 6.4, kế thừa đầy đủ tính năng WooCommerce. | H14: Thiết kế hệ thống TMDT/Trúc Uyên/ | I14: [TỰ THIẾT KẾ TỰ CODE] Dựa trên Figma Design Tokens của chính mình | J14: Chuẩn PSR-12; Pure PHP/CSS BEM; Không dùng Elementor; Ajax filter dùng wp_ajax_ & taxonomy; Mobile-first; Điểm Lighthouse >= 80. | K14: Theme kích hoạt thành công trên WordPress 6.4, kế thừa đầy đủ tính năng WooCommerce. | L14: Lâm Trúc Uyên | M14: Theme Dev 1 (Catalog, UI) | N14: Lê Nguyễn Quốc An | O14: Tuần 03 | P14: =VLOOKUP(O14,'Danh mục'!$A$3:$D$12,2,FALSE) -> 46300 | Q14: =VLOOKUP(O14,'Danh mục'!$A$3:$D$12,3,FALSE) -> 46306 | S14: Cao | T14: Backlog | U14: Không | V14: TASK-21 | Y14: =IF(AND(TODAY()>Q14,T14<>"Done"),"TRỄ",IF(AND(C14="G4",VLOOKUP(B14,DoR!$A$2:$K$12,11,FALSE)<>"SẴN SÀNG PROMPT"),"THIẾU ĐẦU VÀO","")) -> TRỄ
A15: L03-G2-01 | B15: L03 | C15: G2 | D15: Vẽ sơ đồ Activity diagram quy trình thêm vào giỏ và tính chiết khấu Combo | E15: Vẽ sơ đồ Activity bằng draw.io tại docs/flows/L03-cart-combo/activity.drawio thể hiện luồng thêm 1-click Routine và kiểm tra điều kiện áp dụng giảm giá 15%. | F15: Flow Card L03 và công thức chiết khấu | G15: File docs/flows/L03-cart-combo/activity.drawio + PNG | H15: Thiết kế hệ thống TMDT/Nhã Uyên/ | I15: [NGƯỜI VẼ] L03_Cart_Combo_Discount_Activity.drawio | J15: Sơ đồ Activity luồng 1-click thêm routine; rẽ nhánh giảm 15%; bắt xung đột Retinol/AHA; Bắt buộc lưu file .drawio gốc, cấm up ảnh. | K15: Có đầy đủ nhánh kiểm tra số lượng SP trong routine, nhánh cảnh báo xung đột thành phần và hiển thị giá tiết kiệm. | L15: Huỳnh Ngọc Nhã Uyên | M15: Theme Dev 2 (Quiz Frontend, Cart/Checkout UX) | N15: Nguyễn Tấn Phát | O15: Tuần 03 | P15: =VLOOKUP(O15,'Danh mục'!$A$3:$D$12,2,FALSE) -> 46300 | Q15: =VLOOKUP(O15,'Danh mục'!$A$3:$D$12,3,FALSE) -> 46306 | R15: L03-G1-01 | S15: Cao | T15: Backlog | U15: Không | Y15: =IF(AND(TODAY()>Q15,T15<>"Done"),"TRỄ",IF(AND(C15="G4",VLOOKUP(B15,DoR!$A$2:$K$12,11,FALSE)<>"SẴN SÀNG PROMPT"),"THIẾU ĐẦU VÀO","")) -> TRỄ
A16: L04-G2-01 | B16: L04 | C16: G2 | D16: Vẽ Sequence diagram quy trình thanh toán trực tuyến qua cổng VNPay Sandbox | E16: Vẽ Sequence diagram bằng Mermaid tại docs/flows/L04-checkout-payment/sequence.md thể hiện các bước gửi request tạo URL thanh toán, redirect và nhận IPN callback. | F16: Flow Card L04 và tài liệu API VNPay | G16: File docs/flows/L04-checkout-payment/sequence.md | H16: Thiết kế hệ thống TMDT/Minh Tuyền/ | I16: [NGƯỜI VẼ] L04_Checkout_VNPay_Sequence.drawio | J16: Sequence diagram tạo URL thanh toán, tính chữ ký SHA512, redirect VNPay Sandbox và nhận IPN callback; Up file .drawio gốc. | K16: Sơ đồ thể hiện đầy đủ kiểm tra mã băm checksum SHA512, cập nhật trạng thái đơn Đang xử lý và xử lý hủy giao dịch. | L16: Trần Ngọc Minh Tuyền | M16: Integration Dev (thanh toán, email, vận chuyển, REST API) | N16: Lê Nguyễn Quốc An | O16: Tuần 03 | P16: =VLOOKUP(O16,'Danh mục'!$A$3:$D$12,2,FALSE) -> 46300 | Q16: =VLOOKUP(O16,'Danh mục'!$A$3:$D$12,3,FALSE) -> 46306 | R16: TASK-04 | S16: Cao | T16: Backlog | U16: 46058 | Y16: =IF(AND(TODAY()>Q16,T16<>"Done"),"TRỄ",IF(AND(C16="G4",VLOOKUP(B16,DoR!$A$2:$K$12,11,FALSE)<>"SẴN SÀNG PROMPT"),"THIẾU ĐẦU VÀO","")) -> TRỄ
A17: L04-G5-02 | B17: L04 | C17: G5 | D17: Cài đặt và tích hợp Plugin cổng thanh toán VNPay Sandbox; Cấu hình thông số TmnCode, HashSecret; Kiểm tra tính hợp lệ của chữ ký dữ liệu SHA512. | E17: Cài đặt và tích hợp Plugin cổng thanh toán VNPay Sandbox; Cấu hình thông số TmnCode, HashSecret; Kiểm tra tính hợp lệ của chữ ký dữ liệu SHA512. | F17: Tài liệu yêu cầu dự án và dữ liệu từ các luồng liên quan | G17: Thanh toán thử nghiệm thành công bằng thẻ test VNPay, trạng thái đơn chuyển sang Đang xử lý. | H17: Thiết kế hệ thống TMDT/Minh Tuyền/ | I17: [TỰ VẼ TỰ CODE] Lấy từ bản vẽ L04-G2-01 của chính mình | J17: Kế thừa WC_Payment_Gateway; Chữ ký SHA512; Secret key đặt tại wp-config; Validate IPN callback; Cấm lưu số thẻ thô. | K17: Thanh toán thử nghiệm thành công bằng thẻ test VNPay, trạng thái đơn chuyển sang Đang xử lý. | L17: Trần Ngọc Minh Tuyền | M17: Integration Dev (thanh toán, email, vận chuyển, REST API) | N17: Lê Nguyễn Quốc An | O17: Tuần 03 | P17: =VLOOKUP(O17,'Danh mục'!$A$3:$D$12,2,FALSE) -> 46300 | Q17: =VLOOKUP(O17,'Danh mục'!$A$3:$D$12,3,FALSE) -> 46306 | S17: Khẩn cấp | T17: Backlog | U17: 46058 | V17: TASK-20 | Y17: =IF(AND(TODAY()>Q17,T17<>"Done"),"TRỄ",IF(AND(C17="G4",VLOOKUP(B17,DoR!$A$2:$K$12,11,FALSE)<>"SẴN SÀNG PROMPT"),"THIẾU ĐẦU VÀO","")) -> TRỄ
A18: L01-G4-01 | B18: L01 | C18: G4 | D18: Soạn Prompt cho AI agent sinh mã nguồn Quiz Engine và weighted matching L01 | E18: Áp dụng Mẫu Prompt chuẩn viết prompt yêu cầu AI agent sinh class Quiz_Engine xử lý tính điểm weighted tag matching và REST endpoint. | F18: Flow Card L01, Quiz Decision Matrix và sơ đồ luồng | G18: Prompt hoàn chỉnh được ghi vào tab Prompt Log với mã PRM-L01-01 | H18: Thiết kế hệ thống TMDT/Hiếu Nhân/ | I18: [CODE NHẬN BẢN VẼ] Lấy file L01_Quiz_Logic_Flowchart.drawio (từ task L01-G2-01 của Huỳnh Ngọc Nhã Uyên) | J18: WordPress REST API Controller; Check nonce CSRF; Endpoint /wp-json/unisex-quiz/v1/recommend; Thuật toán weighted matching; Trả JSON 4 bước chuẩn; Cơ chế Safe Fallback khi rỗng. | K18: Prompt nêu rõ tên class, phương thức calculate_routine(), bảng meta liên quan và 5 ca test Given-When-Then. | L18: Bùi Hiếu Nhân | M18: Plugin Dev 1 (Quiz Backend, Taxonomy, REST) | N18: Lê Nguyễn Quốc An | O18: Tuần 04 | P18: =VLOOKUP(O18,'Danh mục'!$A$3:$D$12,2,FALSE) -> 46307 | Q18: =VLOOKUP(O18,'Danh mục'!$A$3:$D$12,3,FALSE) -> 46313 | R18: L01-G3-01 | S18: Khẩn cấp | T18: Backlog | U18: Không | Y18: =IF(AND(TODAY()>Q18,T18<>"Done"),"TRỄ",IF(AND(C18="G4",VLOOKUP(B18,DoR!$A$2:$K$12,11,FALSE)<>"SẴN SÀNG PROMPT"),"THIẾU ĐẦU VÀO","")) -> TRỄ
